Workbook

Sheet README
B2: Last-Mile Misdelivery: Cost Impact & Verification ROI Model
B3: Supply chain / operations analysis • Portfolio project
B5: PURPOSE
B6: Wrong-address deliveries are one of the most persistent and costly failures in last-mile logistics. This model quantifies the annual cost of address-caused delivery failures across the US parcel market, then estimates how much of that cost a doorstep verification system could recover under conservative, moderate, and optimistic assumptions. It is a decision-support tool: it turns a known operational pain point into sized, defensible numbers.
B8: METHODOLOGY
B9: 1. Establish the addressable problem: parcel volume x first-attempt failure rate x share of failures caused by address/location errors x cost per failed delivery.
B10: 2. Model a verification intervention: for the share of volume that adopts the system, estimate failures prevented (effectiveness) and value recovered, net of the system's operating cost.
B11: 3. Stress-test the result across adoption and effectiveness levels (Scenarios tab) so the conclusion does not depend on best-case assumptions.
B13: HOW TO USE
B14: All inputs live on the Assumptions tab in blue. Change any blue cell and every downstream number and chart updates. Black = calculated in-sheet; green = pulled from another tab.
B16: KEY SOURCES (verify and update before external use)
B17: • US parcel volume ~24.6B/yr (2026 est) — Pitney Bowes / SellersCommerce
... B24: Benchmark figures are illustrative industry estimates gathered from public sources and should be re-verified before any external use. Effectiveness and cost-per-verification are modeling assumptions used to demonstrate methodology, not validated performance claims.

Sheet Assumptions
B2: Assumptions & Inputs
B3: Blue = editable input. Change these to drive the whole model.
B5: Parameter | C5: Value | D5: Unit | E5: Source / Note
B6: Annual US parcel volume | C6: 24600000000 | D6: parcels | E6: Pitney Bowes / SellersCommerce, 2026 est.
B7: First-attempt failure rate | C7: 0.08 | D7: % | E7: Loqate / Harvard Business Review
B8: Address-error share of failures | C8: 0.45 | D8: % | E8: Shipsy, 2024
B9: Cost per failed delivery | C9: 17.2 | D9: $ | E9: Loqate
B10: Verification effectiveness (default) | C10: 0.7 | D10: % reduction | E10: ANALYST ASSUMPTION — reduction in address-caused failures on covered volume
B11: Operating cost per verification | C11: 0.15 | D11: $ | E11: ANALYST ASSUMPTION — NFC tag amortization + app/API integration per delivery

Sheet Cost Model
B2: Baseline: Sizing the Addressable Problem
B3: The annual cost of address-caused delivery failures at current-state performance.
B5: Line item | C5: Value | D5: Unit | E5: Basis
B6: Annual US parcel volume | C6: =Assumptions!C6 | D6: parcels | E6: Input
B7: First-attempt failure rate | C7: =Assumptions!C7 | D7: % | E7: Input
B8: Total failed first attempts | C8: =C6*C7 | D8: deliveries | E8: Volume x failure rate
B9: Address-error share of failures | C9: =Assumptions!C8 | D9: % | E9: Input
B10: Address-caused failures (addressable) | C10: =C8*C9 | D10: deliveries | E10: Failures x address share
B11: Cost per failed delivery | C11: =Assumptions!C9 | D11: $ | E11: Input
B12: ADDRESSABLE PROBLEM (annual cost) | C12: =C10*C11 | D12: $/yr | E12: Addressable failures x cost
B15: Read: this is the pool of money currently lost each year to wrong-address failures — the ceiling on what any verification fix could recover.

Sheet Scenarios
B2: Scenario Analysis: Value Recovered by a Verification System
B3: Not all volume adopts, and no system is perfect. Three cases bracket the outcome.
B5: Scenario inputs
C6: Conservative | D6: Moderate | E6: Optimistic
B7: Adoption (share of volume covered) | C7: 0.05 | D7: 0.2 | E7: 0.5
B8: Effectiveness (reduction of address failures) | C8: 0.6 | D8: 0.75 | E8: 0.9
B10: Results
C11: Conservative | D11: Moderate | E11: Optimistic
B12: Covered volume | C12: =Assumptions!$C$6*C7 | D12: =Assumptions!$C$6*D7 | E12: =Assumptions!$C$6*E7
B13: Address failures in covered volume | C13: =C12*Assumptions!$C$7*Assumptions!$C$8 | D13: =D12*Assumptions!$C$7*Assumptions!$C$8 | E13: =E12*Assumptions!$C$7*Assumptions!$C$8
B14: Failures prevented | C14: =C13*C8 | D14: =D13*D8 | E14: =E13*E8
B15: Value recovered ($/yr) | C15: =C14*Assumptions!$C$9 | D15: =D14*Assumptions!$C$9 | E15: =E14*Assumptions!$C$9
B16: System operating cost ($/yr) | C16: =C12*Assumptions!$C$11 | D16: =D12*Assumptions!$C$11 | E16: =E12*Assumptions!$C$11
B17: NET value recovered ($/yr) | C17: =C15-C16 | D17: =D15-D16 | E17: =E15-E16
B18: Benefit-cost ratio (recovered / cost) | C18: =C15/C16 | D18: =D15/D16 | E18: =E15/E16
B21: Sensitivity: NET value recovered ($/yr)
B22: Rows = adoption | Columns = effectiveness
B23: Adoption \ Effectiveness | C23: 0.6 | D23: 0.7 | E23: 0.8 | F23: 0.9
B24: 0.05 | C24: =(Assumptions!$C$6*$B24*Assumptions!$C$7*Assumptions!$C$8*C$23*Assumptions!$C$9)-(Assumptions!$C$6*$B24*Assumptions!$C$11) | D24: =(Assumptions!$C$6*$B24*Assumptions!$C$7*Assumptions!$C$8*D$23*Assumptions!$C$9)-(Assumptions!$C$6*$B24*Assumptions!$C$11) | E24: =(Assumptions!$C$6*$B24*Assumptions!$C$7*Assumptions!$C$8*E$23*Assumptions!$C$9)-(Assumptions!$C$6*$B24*Assumptions!$C$11) | F24: =(Assumptions!$C$6*$B24*Assumptions!$C$7*Assumptions!$C$8*F$23*Assumptions!$C$9)-(Assumptions!$C$6*$B24*Assumptions!$C$11)
B25: 0.1 | C25: =(Assumptions!$C$6*$B25*Assumptions!$C$7*Assumptions!$C$8*C$23*Assumptions!$C$9)-(Assumptions!$C$6*$B25*Assumptions!$C$11) | D25: =(Assumptions!$C$6*$B25*Assumptions!$C$7*Assumptions!$C$8*D$23*Assumptions!$C$9)-(Assumptions!$C$6*$B25*Assumptions!$C$11) | E25: =(Assumptions!$C$6*$B25*Assumptions!$C$7*Assumptions!$C$8*E$23*Assumptions!$C$9)-(Assumptions!$C$6*$B25*Assumptions!$C$11) | F25: =(Assumptions!$C$6*$B25*Assumptions!$C$7*Assumptions!$C$8*F$23*Assumptions!$C$9)-(Assumptions!$C$6*$B25*Assumptions!$C$11)
B26: 0.2 | C26: =(Assumptions!$C$6*$B26*Assumptions!$C$7*Assumptions!$C$8*C$23*Assumptions!$C$9)-(Assumptions!$C$6*$B26*Assumptions!$C$11) | D26: =(Assumptions!$C$6*$B26*Assumptions!$C$7*Assumptions!$C$8*D$23*Assumptions!$C$9)-(Assumptions!$C$6*$B26*Assumptions!$C$11) | E26: =(Assumptions!$C$6*$B26*Assumptions!$C$7*Assumptions!$C$8*E$23*Assumptions!$C$9)-(Assumptions!$C$6*$B26*Assumptions!$C$11) | F26: =(Assumptions!$C$6*$B26*Assumptions!$C$7*Assumptions!$C$8*F$23*Assumptions!$C$9)-(Assumptions!$C$6*$B26*Assumptions!$C$11)
B27: 0.35 | C27: =(Assumptions!$C$6*$B27*Assumptions!$C$7*Assumptions!$C$8*C$23*Assumptions!$C$9)-(Assumptions!$C$6*$B27*Assumptions!$C$11) | D27: =(Assumptions!$C$6*$B27*Assumptions!$C$7*Assumptions!$C$8*D$23*Assumptions!$C$9)-(Assumptions!$C$6*$B27*Assumptions!$C$11) | E27: =(Assumptions!$C$6*$B27*Assumptions!$C$7*Assumptions!$C$8*E$23*Assumptions!$C$9)-(Assumptions!$C$6*$B27*Assumptions!$C$11) | F27: =(Assumptions!$C$6*$B27*Assumptions!$C$7*Assumptions!$C$8*F$23*Assumptions!$C$9)-(Assumptions!$C$6*$B27*Assumptions!$C$11)
B28: 0.5 | C28: =(Assumptions!$C$6*$B28*Assumptions!$C$7*Assumptions!$C$8*C$23*Assumptions!$C$9)-(Assumptions!$C$6*$B28*Assumptions!$C$11) | D28: =(Assumptions!$C$6*$B28*Assumptions!$C$7*Assumptions!$C$8*D$23*Assumptions!$C$9)-(Assumptions!$C$6*$B28*Assumptions!$C$11) | E28: =(Assumptions!$C$6*$B28*Assumptions!$C$7*Assumptions!$C$8*E$23*Assumptions!$C$9)-(Assumptions!$C$6*$B28*Assumptions!$C$11) | F28: =(Assumptions!$C$6*$B28*Assumptions!$C$7*Assumptions!$C$8*F$23*Assumptions!$C$9)-(Assumptions!$C$6*$B28*Assumptions!$C$11)

Sheet Dashboard
B2: Dashboard — Headline Findings
B3: US parcel market, annual basis. See Assumptions for inputs.
B5: Addressable problem ($/yr) | E5: Moderate net recovered ($/yr)
B6: ='Cost Model'!C12 | E6: =Scenarios!D17
B8: Moderate benefit-cost ratio | E8: Addressable failures (parcels/yr)
B9: =Scenarios!D18 | E9: ='Cost Model'!C10
B11: First-attempt success rate
B12: Current (baseline) | C12: =1-Assumptions!C7
B13: With verification (moderate adoption) | C13: =(1-Assumptions!C7)+(Scenarios!D14/Assumptions!C6)
B16: Net value recovered by scenario ($/yr)
B17: Conservative | C17: =Scenarios!C17
B18: Moderate | C18: =Scenarios!D17
B19: Optimistic | C19: =Scenarios!E17
B22: Operational Diagnostic — Simulated ERP Data (1,000 deliveries)
B24: First-Attempt Rate | D24: OTIF Rate | F24: Worst Failure Combo
B25: 0.838 | D25: 0.746 | F25: 0.4571
B27: Worst-performing combination: Coastal Express in Southwest region
B28: Top failure cause: CARRIER_DELAY (51.23% of all failures)
B29: See 'SQL Diagnostic Summary' and 'Data Cleaning (Excel)' tabs for full methodology and query documentation.

Sheet ERP Raw Export (Sample)
B2: Simulated SAP SD Delivery Export — Raw Pull
B3: First 150 of 1,020 raw records as pulled from the ERP report, before cleaning. Note inconsistent date formats, casing, and duplicate rows — typical of a real export.
B5: Delivery_ID | C5: Order_ID | D5: Region | E5: Carrier | F5: Ship_Date | G5: Promised_Delivery_Date | H5: Actual_Delivery_Date | I5: Delivery_Status | J5: Failure_Reason_Code | K5: Order_Complete | L5: Distance_Miles
B6: 100000 | C6: 200000 | D6: Southeast | E6: Apex Freight | F6: 2025-11-05 | G6: 11/08/2025 | H6: 11/08/2025 | I6: Delivered | K6: Y | L6: 47
B7: 100001 | C7: 200001 | D7: Northeast | E7: apex freight | F7: 28-Oct-2025 | G7: 10/31/2025 | H7: 02-Nov-2025 | I7: Delivered - Late | K7: Y | L7: 573
B8: 100002 | C8: 200002 | D8: PACIFIC NORTHWEST | E8: Northline Logistics | F8: 27-Nov-2025 | G8: 02-Dec-2025 | H8: 02-Dec-2025 | I8: Delivered | K8: Y | L8: 363
B9: 100003 | C9: 200003 | D9: West | E9: Northline Logistics | F9: 28-Oct-2025 | G9: 31-Oct-2025 | I9: Failed - Carrier Delay | J9: CARRIER_DELAY | L9: 404
B10: 100004 | C10: 200004 | D10: Southeast | E10: Coastal Express | F10: 2025-11-14 | G10: 19-Nov-2025 | H10: 2025-11-23 | I10: DELIVERED - LATE | K10: Y | L10: 402
B11: 100005 | C11: 200005 | D11: Southeast | E11: Coastal Express | F11: 12/20/2025 | G11: 12/25/2025 | H11: 12/25/2025 | I11: Delivered | K11: Y | L11: 61
B12: 100006 | C12: 200006 | D12: Southwest | E12: Coastal Express | F12: 2025-10-11 | G12: 10/14/2025 | H12: 13-Oct-2025 | I12: Delivered | K12: Y | L12: 388
B13: 100007 | C13: 200007 | D13: Midwest | E13: Coastal Express | F13: 11/15/2025 | G13: 11/18/2025 | H13: 2025-11-18 | I13: Delivered | K13: Y | L13: 190
B14: 100008 | C14: 200008 | D14: Southwest | E14: Northline Logistics | F14: 2025-11-29 | G14: 12/03/2025 | H14: 12/03/2025 | I14: Delivered | K14: Y | L14: 72
B15: 100009 | C15: 200009 | D15: Southwest | E15: Apex Freight | F15: 2025-11-10 | G15: 2025-11-14 | H15: 13-Nov-2025 | I15: Delivered | K15: Y | L15: 526
B16: 100010 | C16: 200010 | D16: Pacific Northwest | E16: Summit Carriers | F16: 10/19/2025 | G16: 10/22/2025 | H16: 2025-10-21 | I16: Delivered | K16: Y | L16: 453
B17: 100011 | C17: 200011 | D17: Pacific Northwest | E17: Coastal Express | F17: 2025-10-29 | G17: 2025-11-01 | H17: 01-Nov-2025 | I17: Delivered | K17: Y | L17: 171
B18: 100012 | C18: 200012 | D18: Midwest | E18: Summit Carriers | F18: 16-Dec-2025 | G18: 12/18/2025 | H18: 12/17/2025 | I18: Delivered | K18: Y | L18: 581
B19: 100013 | C19: 200013 | D19: Northeast | E19: Apex Freight | F19: 27-Dec-2025 | G19: 01/01/2026 | H19: 2025-12-31 | I19: Delivered | K19: Y | L19: 460
B20: 100014 | C20: 200014 | D20: Midwest | E20: Summit Carriers | F20: 10/01/2025 | G20: 2025-10-04 | H20: 2025-10-04 | I20: DELIVERED | K20: Y | L20: 320
B21: 100015 | C21: 200015 | D21: Southwest | E21: Northline Logistics | F21: 17-Nov-2025 | G21: 11/20/2025 | H21: 20-Nov-2025 | I21: Delivered | K21: Y | L21: 515
... B25: 100019 | C25: 200019 | D25: Mid-Atlantic | E25: Apex Freight | F25: 2025-12-15 | G25: 12/20/2025 | H25: 12/20/2025 | I25: Delivered | K25: Y | L25: 75
B26: 100020 | C26: 200020 | D26: Southwest | E26: Apex Freight | F26: 2025-10-05 | G26: 2025-10-08 | I26: Failed - Carrier Delay | J26: CARRIER_DELAY | L26: 258
B27: 100021 | C27: 200021 | D27: West | E27: Summit Carriers | F27: 2025-10-28 | G27: 2025-11-02 | H27: 01-Nov-2025 | I27: Delivered | K27: Y | L27: 499
B28: 100022 | C28: 200022 | D28: Pacific Northwest | E28: NORTHLINE LOGISTICS | F28: 2025-10-13 | G28: 15-Oct-2025 | H28: 10/14/2025 | I28: Delivered | K28: Y | L28: 70
B29: 100023 | C29: 200023 | D29: Southeast | E29: Apex Freight | F29: 2025-11-21 | G29: 2025-11-24 | H29: 24-Nov-2025 | I29: Delivered | K29: Y | L29: 474
B30: 100024 | C30: 200024 | D30: Midwest | E30: Summit Carriers | F30: 2025-10-24 | G30: 27-Oct-2025 | H30: 10/27/2025 | I30: Delivered | K30: Y | L30: 578
B31: 100025 | C31: 200025 | D31: Southeast | E31: Apex Freight | F31: 23-Dec-2025 | G31: 28-Dec-2025 | H31: 28-Dec-2025 | I31: Delivered | K31: Y | L31: 512
B32: 100026 | C32: 200026 | D32: Mountain | E32: Northline Logistics | F32: 21-Nov-2025 | G32: 11/23/2025 | I32: Failed - Carrier Delay | J32: CARRIER_DELAY | L32: 17
B33: 100027 | C33: 200027 | D33: PACIFIC NORTHWEST | E33: coastal express | F33: 2025-11-28 | G33: 12/01/2025 | H33: 30-Nov-2025 | I33: Delivered | K33: Y | L33: 318
B34: 100028 | C34: 200028 | D34: Southwest | E34: Apex Freight | F34: 12/14/2025 | G34: 2025-12-19 | I34: Failed - Carrier Delay | J34: CARRIER_DELAY | L34: 336
B35: 100029 | C35: 200029 | E35: Apex Freight | F35: 2025-12-14 | G35: 2025-12-18 | H35: 2025-12-18 | I35: Delivered | K35: Y | L35: 535
B36: 100030 | C36: 200030 | D36: Southeast | E36: Northline Logistics | F36: 10/09/2025 | G36: 2025-10-14 | I36: failed - carrier delay | J36: CARRIER_DELAY | L36: 255
B37: 100031 | C37: 200031 | D37: Pacific Northwest | E37: Apex Freight | F37: 12-Dec-2025 | G37: 12/15/2025 | H37: 16-Dec-2025 | I37: Delivered - Late | K37: Y | L37: 612
B38: 100032 | C38: 200032 | D38: Mid-Atlantic | E38: Coastal Express | F38: 2025-10-27 | G38: 30-Oct-2025 | H38: 2025-10-29 | I38: delivered | K38: Y | L38: 89
B39: 100033 | C39: 200033 | D39: Northeast | E39: Summit Carriers | F39: 12/19/2025 | G39: 2025-12-24 | H39: 24-Dec-2025 | I39: Delivered | K39: Y | L39: 150
B40: 100034 | C40: 200034 | D40: Mid-Atlantic | E40: Apex Freight | F40: 11/01/2025 | G40: 04-Nov-2025 | H40: 11/03/2025 | I40: Delivered | K40: Y | L40: 556
B41: 100035 | C41: 200035 | D41: Northeast | E41: Coastal Express | F41: 12/24/2025 | G41: 12/26/2025 | H41: 2025-12-26 | I41: delivered | K41: Y | L41: 581
B42: 100036 | C42: 200036 | D42: Midwest | E42: COASTAL EXPRESS | F42: 11/06/2025 | G42: 2025-11-11 | H42: 11/10/2025 | I42: Delivered | K42: Y | L42: 272
B43: 100037 | C43: 200037 | D43: Northeast | E43: Apex Freight | F43: 12/21/2025 | G43: 12/25/2025 | H43: 12/28/2025 | I43: Delivered - Late | K43: Y | L43: 283
B44: 100038 | C44: 200038 | D44: MIDWEST | E44: Summit Carriers | F44: 10-Dec-2025 | G44: 2025-12-14 | H44: 12/14/2025 | I44: Delivered | K44: Y | L44: 393
B45: 100039 | C45: 200039 | D45: Midwest | E45: Summit Carriers | F45: 17-Oct-2025 | G45: 2025-10-19 | H45: 10/19/2025 | I45: delivered | K45: Y | L45: 230
...

Sheet Data Cleaning (Excel)
B2: Data Cleaning — Excel Formulas
B3: TRIM/CLEAN standardize messy raw fields; IFERROR keeps output clean when data is missing. First 100 records shown.
B5: Delivery_ID | C5: Region_RAW | D5: Region_CLEAN | E5: Carrier_RAW | F5: Carrier_CLEAN | G5: Status_RAW | H5: Status_CLEAN | I5: Lead_Time_Days (NETWORKDAYS)
B6: 100000 | C6: Southeast | D6: =IFERROR(PROPER(TRIM(CLEAN(C6))),"Unknown") | E6: Apex Freight | F6: =IFERROR(PROPER(TRIM(CLEAN(E6))),"Unknown") | G6: Delivered | H6: =IFERROR(PROPER(TRIM(CLEAN(G6))),"Unknown") | I6: =IFERROR(NETWORKDAYS(DATEVALUE("2025-11-05"),DATEVALUE("11/08/2025")),"N/A")
B7: 100001 | C7: Northeast | D7: =IFERROR(PROPER(TRIM(CLEAN(C7))),"Unknown") | E7: apex freight | F7: =IFERROR(PROPER(TRIM(CLEAN(E7))),"Unknown") | G7: Delivered - Late | H7: =IFERROR(PROPER(TRIM(CLEAN(G7))),"Unknown") | I7: =IFERROR(NETWORKDAYS(DATEVALUE("28-Oct-2025"),DATEVALUE("10/31/2025")),"N/A")
B8: 100002 | C8: PACIFIC NORTHWEST | D8: =IFERROR(PROPER(TRIM(CLEAN(C8))),"Unknown") | E8: Northline Logistics | F8: =IFERROR(PROPER(TRIM(CLEAN(E8))),"Unknown") | G8: Delivered | H8: =IFERROR(PROPER(TRIM(CLEAN(G8))),"Unknown") | I8: =IFERROR(NETWORKDAYS(DATEVALUE("27-Nov-2025"),DATEVALUE("02-Dec-2025")),"N/A")
B9: 100003 | C9: West | D9: =IFERROR(PROPER(TRIM(CLEAN(C9))),"Unknown") | E9: Northline Logistics | F9: =IFERROR(PROPER(TRIM(CLEAN(E9))),"Unknown") | G9: Failed - Carrier Delay | H9: =IFERROR(PROPER(TRIM(CLEAN(G9))),"Unknown") | I9: =IFERROR(NETWORKDAYS(DATEVALUE("28-Oct-2025"),DATEVALUE("31-Oct-2025")),"N/A")
B10: 100004 | C10: Southeast | D10: =IFERROR(PROPER(TRIM(CLEAN(C10))),"Unknown") | E10: Coastal Express | F10: =IFERROR(PROPER(TRIM(CLEAN(E10))),"Unknown") | G10: DELIVERED - LATE | H10: =IFERROR(PROPER(TRIM(CLEAN(G10))),"Unknown") | I10: =IFERROR(NETWORKDAYS(DATEVALUE("2025-11-14"),DATEVALUE("19-Nov-2025")),"N/A")
B11: 100005 | C11: Southeast | D11: =IFERROR(PROPER(TRIM(CLEAN(C11))),"Unknown") | E11: Coastal Express | F11: =IFERROR(PROPER(TRIM(CLEAN(E11))),"Unknown") | G11: Delivered | H11: =IFERROR(PROPER(TRIM(CLEAN(G11))),"Unknown") | I11: =IFERROR(NETWORKDAYS(DATEVALUE("12/20/2025"),DATEVALUE("12/25/2025")),"N/A")
B12: 100006 | C12: Southwest | D12: =IFERROR(PROPER(TRIM(CLEAN(C12))),"Unknown") | E12: Coastal Express | F12: =IFERROR(PROPER(TRIM(CLEAN(E12))),"Unknown") | G12: Delivered | H12: =IFERROR(PROPER(TRIM(CLEAN(G12))),"Unknown") | I12: =IFERROR(NETWORKDAYS(DATEVALUE("2025-10-11"),DATEVALUE("10/14/2025")),"N/A")
B13: 100007 | C13: Midwest | D13: =IFERROR(PROPER(TRIM(CLEAN(C13))),"Unknown") | E13: Coastal Express | F13: =IFERROR(PROPER(TRIM(CLEAN(E13))),"Unknown") | G13: Delivered | H13: =IFERROR(PROPER(TRIM(CLEAN(G13))),"Unknown") | I13: =IFERROR(NETWORKDAYS(DATEVALUE("11/15/2025"),DATEVALUE("11/18/2025")),"N/A")
B14: 100008 | C14: Southwest | D14: =IFERROR(PROPER(TRIM(CLEAN(C14))),"Unknown") | E14: Northline Logistics | F14: =IFERROR(PROPER(TRIM(CLEAN(E14))),"Unknown") | G14: Delivered | H14: =IFERROR(PROPER(TRIM(CLEAN(G14))),"Unknown") | I14: =IFERROR(NETWORKDAYS(DATEVALUE("2025-11-29"),DATEVALUE("12/03/2025")),"N/A")
B15: 100009 | C15: Southwest | D15: =IFERROR(PROPER(TRIM(CLEAN(C15))),"Unknown") | E15: Apex Freight | F15: =IFERROR(PROPER(TRIM(CLEAN(E15))),"Unknown") | G15: Delivered | H15: =IFERROR(PROPER(TRIM(CLEAN(G15))),"Unknown") | I15: =IFERROR(NETWORKDAYS(DATEVALUE("2025-11-10"),DATEVALUE("2025-11-14")),"N/A")
B16: 100010 | C16: Pacific Northwest | D16: =IFERROR(PROPER(TRIM(CLEAN(C16))),"Unknown") | E16: Summit Carriers | F16: =IFERROR(PROPER(TRIM(CLEAN(E16))),"Unknown") | G16: Delivered | H16: =IFERROR(PROPER(TRIM(CLEAN(G16))),"Unknown") | I16: =IFERROR(NETWORKDAYS(DATEVALUE("10/19/2025"),DATEVALUE("10/22/2025")),"N/A")
B17: 100011 | C17: Pacific Northwest | D17: =IFERROR(PROPER(TRIM(CLEAN(C17))),"Unknown") | E17: Coastal Express | F17: =IFERROR(PROPER(TRIM(CLEAN(E17))),"Unknown") | G17: Delivered | H17: =IFERROR(PROPER(TRIM(CLEAN(G17))),"Unknown") | I17: =IFERROR(NETWORKDAYS(DATEVALUE("2025-10-29"),DATEVALUE("2025-11-01")),"N/A")
B18: 100012 | C18: Midwest | D18: =IFERROR(PROPER(TRIM(CLEAN(C18))),"Unknown") | E18: Summit Carriers | F18: =IFERROR(PROPER(TRIM(CLEAN(E18))),"Unknown") | G18: Delivered | H18: =IFERROR(PROPER(TRIM(CLEAN(G18))),"Unknown") | I18: =IFERROR(NETWORKDAYS(DATEVALUE("16-Dec-2025"),DATEVALUE("12/18/2025")),"N/A")
B19: 100013 | C19: Northeast | D19: =IFERROR(PROPER(TRIM(CLEAN(C19))),"Unknown") | E19: Apex Freight | F19: =IFERROR(PROPER(TRIM(CLEAN(E19))),"Unknown") | G19: Delivered | H19: =IFERROR(PROPER(TRIM(CLEAN(G19))),"Unknown") | I19: =IFERROR(NETWORKDAYS(DATEVALUE("27-Dec-2025"),DATEVALUE("01/01/2026")),"N/A")
B20: 100014 | C20: Midwest | D20: =IFERROR(PROPER(TRIM(CLEAN(C20))),"Unknown") | E20: Summit Carriers | F20: =IFERROR(PROPER(TRIM(CLEAN(E20))),"Unknown") | G20: DELIVERED | H20: =IFERROR(PROPER(TRIM(CLEAN(G20))),"Unknown") | I20: =IFERROR(NETWORKDAYS(DATEVALUE("10/01/2025"),DATEVALUE("2025-10-04")),"N/A")
B21: 100015 | C21: Southwest | D21: =IFERROR(PROPER(TRIM(CLEAN(C21))),"Unknown") | E21: Northline Logistics | F21: =IFERROR(PROPER(TRIM(CLEAN(E21))),"Unknown") | G21: Delivered | H21: =IFERROR(PROPER(TRIM(CLEAN(G21))),"Unknown") | I21: =IFERROR(NETWORKDAYS(DATEVALUE("17-Nov-2025"),DATEVALUE("11/20/2025")),"N/A")
B22: 100016 | C22: Northeast | D22: =IFERROR(PROPER(TRIM(CLEAN(C22))),"Unknown") | E22: Apex Freight | F22: =IFERROR(PROPER(TRIM(CLEAN(E22))),"Unknown") | G22: Delivered | H22: =IFERROR(PROPER(TRIM(CLEAN(G22))),"Unknown") | I22: =IFERROR(NETWORKDAYS(DATEVALUE("16-Nov-2025"),DATEVALUE("19-Nov-2025")),"N/A")
B23: 100017 | C23: Southeast | D23: =IFERROR(PROPER(TRIM(CLEAN(C23))),"Unknown") | E23: Northline Logistics | F23: =IFERROR(PROPER(TRIM(CLEAN(E23))),"Unknown") | G23: Delivered | H23: =IFERROR(PROPER(TRIM(CLEAN(G23))),"Unknown") | I23: =IFERROR(NETWORKDAYS(DATEVALUE("10/17/2025"),DATEVALUE("10/21/2025")),"N/A")
B24: 100018 | C24: Southwest | D24: =IFERROR(PROPER(TRIM(CLEAN(C24))),"Unknown") | E24: Coastal Express | F24: =IFERROR(PROPER(TRIM(CLEAN(E24))),"Unknown") | G24: Delivered | H24: =IFERROR(PROPER(TRIM(CLEAN(G24))),"Unknown") | I24: =IFERROR(NETWORKDAYS(DATEVALUE("2025-11-21"),DATEVALUE("11/24/2025")),"N/A")
B25: 100019 | C25: Mid-Atlantic | D25: =IFERROR(PROPER(TRIM(CLEAN(C25))),"Unknown") | E25: Apex Freight | F25: =IFERROR(PROPER(TRIM(CLEAN(E25))),"Unknown") | G25: Delivered | H25: =IFERROR(PROPER(TRIM(CLEAN(G25))),"Unknown") | I25: =IFERROR(NETWORKDAYS(DATEVALUE("2025-12-15"),DATEVALUE("12/20/2025")),"N/A")
B26: 100020 | C26: Southwest | D26: =IFERROR(PROPER(TRIM(CLEAN(C26))),"Unknown") | E26: Apex Freight | F26: =IFERROR(PROPER(TRIM(CLEAN(E26))),"Unknown") | G26: Failed - Carrier Delay | H26: =IFERROR(PROPER(TRIM(CLEAN(G26))),"Unknown") | I26: =IFERROR(NETWORKDAYS(DATEVALUE("2025-10-05"),DATEVALUE("2025-10-08")),"N/A")
B27: 100021 | C27: West | D27: =IFERROR(PROPER(TRIM(CLEAN(C27))),"Unknown") | E27: Summit Carriers | F27: =IFERROR(PROPER(TRIM(CLEAN(E27))),"Unknown") | G27: Delivered | H27: =IFERROR(PROPER(TRIM(CLEAN(G27))),"Unknown") | I27: =IFERROR(NETWORKDAYS(DATEVALUE("2025-10-28"),DATEVALUE("2025-11-02")),"N/A")
B28: 100022 | C28: Pacific Northwest | D28: =IFERROR(PROPER(TRIM(CLEAN(C28))),"Unknown") | E28: NORTHLINE LOGISTICS | F28: =IFERROR(PROPER(TRIM(CLEAN(E28))),"Unknown") | G28: Delivered | H28: =IFERROR(PROPER(TRIM(CLEAN(G28))),"Unknown") | I28: =IFERROR(NETWORKDAYS(DATEVALUE("2025-10-13"),DATEVALUE("15-Oct-2025")),"N/A")
B29: 100023 | C29: Southeast | D29: =IFERROR(PROPER(TRIM(CLEAN(C29))),"Unknown") | E29: Apex Freight | F29: =IFERROR(PROPER(TRIM(CLEAN(E29))),"Unknown") | G29: Delivered | H29: =IFERROR(PROPER(TRIM(CLEAN(G29))),"Unknown") | I29: =IFERROR(NETWORKDAYS(DATEVALUE("2025-11-21"),DATEVALUE("2025-11-24")),"N/A")
B30: 100024 | C30: Midwest | D30: =IFERROR(PROPER(TRIM(CLEAN(C30))),"Unknown") | E30: Summit Carriers | F30: =IFERROR(PROPER(TRIM(CLEAN(E30))),"Unknown") | G30: Delivered | H30: =IFERROR(PROPER(TRIM(CLEAN(G30))),"Unknown") | I30: =IFERROR(NETWORKDAYS(DATEVALUE("2025-10-24"),DATEVALUE("27-Oct-2025")),"N/A")
B31: 100025 | C31: Southeast | D31: =IFERROR(PROPER(TRIM(CLEAN(C31))),"Unknown") | E31: Apex Freight | F31: =IFERROR(PROPER(TRIM(CLEAN(E31))),"Unknown") | G31: Delivered | H31: =IFERROR(PROPER(TRIM(CLEAN(G31))),"Unknown") | I31: =IFERROR(NETWORKDAYS(DATEVALUE("23-Dec-2025"),DATEVALUE("28-Dec-2025")),"N/A")
B32: 100026 | C32: Mountain | D32: =IFERROR(PROPER(TRIM(CLEAN(C32))),"Unknown") | E32: Northline Logistics | F32: =IFERROR(PROPER(TRIM(CLEAN(E32))),"Unknown") | G32: Failed - Carrier Delay | H32: =IFERROR(PROPER(TRIM(CLEAN(G32))),"Unknown") | I32: =IFERROR(NETWORKDAYS(DATEVALUE("21-Nov-2025"),DATEVALUE("11/23/2025")),"N/A")
B33: 100027 | C33: PACIFIC NORTHWEST | D33: =IFERROR(PROPER(TRIM(CLEAN(C33))),"Unknown") | E33: coastal express | F33: =IFERROR(PROPER(TRIM(CLEAN(E33))),"Unknown") | G33: Delivered | H33: =IFERROR(PROPER(TRIM(CLEAN(G33))),"Unknown") | I33: =IFERROR(NETWORKDAYS(DATEVALUE("2025-11-28"),DATEVALUE("12/01/2025")),"N/A")
B34: 100028 | C34: Southwest | D34: =IFERROR(PROPER(TRIM(CLEAN(C34))),"Unknown") | E34: Apex Freight | F34: =IFERROR(PROPER(TRIM(CLEAN(E34))),"Unknown") | G34: Failed - Carrier Delay | H34: =IFERROR(PROPER(TRIM(CLEAN(G34))),"Unknown") | I34: =IFERROR(NETWORKDAYS(DATEVALUE("12/14/2025"),DATEVALUE("2025-12-19")),"N/A")
B35: 100029 | D35: =IFERROR(PROPER(TRIM(CLEAN(C35))),"Unknown") | E35: Apex Freight | F35: =IFERROR(PROPER(TRIM(CLEAN(E35))),"Unknown") | G35: Delivered | H35: =IFERROR(PROPER(TRIM(CLEAN(G35))),"Unknown") | I35: =IFERROR(NETWORKDAYS(DATEVALUE("2025-12-14"),DATEVALUE("2025-12-18")),"N/A")
B36: 100030 | C36: Southeast | D36: =IFERROR(PROPER(TRIM(CLEAN(C36))),"Unknown") | E36: Northline Logistics | F36: =IFERROR(PROPER(TRIM(CLEAN(E36))),"Unknown") | G36: failed - carrier delay | H36: =IFERROR(PROPER(TRIM(CLEAN(G36))),"Unknown") | I36: =IFERROR(NETWORKDAYS(DATEVALUE("10/09/2025"),DATEVALUE("2025-10-14")),"N/A")
B37: 100031 | C37: Pacific Northwest | D37: =IFERROR(PROPER(TRIM(CLEAN(C37))),"Unknown") | E37: Apex Freight | F37: =IFERROR(PROPER(TRIM(CLEAN(E37))),"Unknown") | G37: Delivered - Late | H37: =IFERROR(PROPER(TRIM(CLEAN(G37))),"Unknown") | I37: =IFERROR(NETWORKDAYS(DATEVALUE("12-Dec-2025"),DATEVALUE("12/15/2025")),"N/A")
B38: 100032 | C38: Mid-Atlantic | D38: =IFERROR(PROPER(TRIM(CLEAN(C38))),"Unknown") | E38: Coastal Express | F38: =IFERROR(PROPER(TRIM(CLEAN(E38))),"Unknown") | G38: delivered | H38: =IFERROR(PROPER(TRIM(CLEAN(G38))),"Unknown") | I38: =IFERROR(NETWORKDAYS(DATEVALUE("2025-10-27"),DATEVALUE("30-Oct-2025")),"N/A")
B39: 100033 | C39: Northeast | D39: =IFERROR(PROPER(TRIM(CLEAN(C39))),"Unknown") | E39: Summit Carriers | F39: =IFERROR(PROPER(TRIM(CLEAN(E39))),"Unknown") | G39: Delivered | H39: =IFERROR(PROPER(TRIM(CLEAN(G39))),"Unknown") | I39: =IFERROR(NETWORKDAYS(DATEVALUE("12/19/2025"),DATEVALUE("2025-12-24")),"N/A")
B40: 100034 | C40: Mid-Atlantic | D40: =IFERROR(PROPER(TRIM(CLEAN(C40))),"Unknown") | E40: Apex Freight | F40: =IFERROR(PROPER(TRIM(CLEAN(E40))),"Unknown") | G40: Delivered | H40: =IFERROR(PROPER(TRIM(CLEAN(G40))),"Unknown") | I40: =IFERROR(NETWORKDAYS(DATEVALUE("11/01/2025"),DATEVALUE("04-Nov-2025")),"N/A")
B41: 100035 | C41: Northeast | D41: =IFERROR(PROPER(TRIM(CLEAN(C41))),"Unknown") | E41: Coastal Express | F41: =IFERROR(PROPER(TRIM(CLEAN(E41))),"Unknown") | G41: delivered | H41: =IFERROR(PROPER(TRIM(CLEAN(G41))),"Unknown") | I41: =IFERROR(NETWORKDAYS(DATEVALUE("12/24/2025"),DATEVALUE("12/26/2025")),"N/A")
B42: 100036 | C42: Midwest | D42: =IFERROR(PROPER(TRIM(CLEAN(C42))),"Unknown") | E42: COASTAL EXPRESS | F42: =IFERROR(PROPER(TRIM(CLEAN(E42))),"Unknown") | G42: Delivered | H42: =IFERROR(PROPER(TRIM(CLEAN(G42))),"Unknown") | I42: =IFERROR(NETWORKDAYS(DATEVALUE("11/06/2025"),DATEVALUE("2025-11-11")),"N/A")
...

Sheet SQL Diagnostic Summary
B2: SQL Diagnostic Analysis — Full Dataset (1,000 records)
B3: Queries run against the cleaned delivery dataset via SQL (SQLite). Results below are the actual query outputs.
B5: Headline KPIs
B6: Total records analyzed | C6: 1000
B7: First-attempt delivery rate | C7: 0.838
B8: OTIF (On-Time, In-Full) | C8: 0.746
B10: Query used — First-Attempt Rate
B11: SELECT ROUND(100.0 * SUM(CASE WHEN Delivery_Status IN ('Delivered','Delivered - Late') THEN 1 ELSE 0 END) / COUNT(*), 2) AS first_attempt_pct FROM deliveries;
B13: Query used — OTIF Rate
B14: SELECT ROUND(100.0 * SUM(CASE WHEN Delivery_Status='Delivered' AND Order_Complete='Y' AND date(Actual_Delivery_Date)<=date(Promised_Delivery_Date) THEN 1 ELSE 0 END) / COUNT(*), 2) AS otif_pct FROM deliveries;
B16: Failure Rate by Region × Carrier (worst combinations)
B17: Region | C17: Carrier | D17: Total Deliveries | E17: Failures | F17: Failure Rate %
B18: Southwest | C18: Coastal Express | D18: 35 | E18: 16 | F18: 0.4571
B19: Southeast | C19: Coastal Express | D19: 37 | E19: 11 | F19: 0.2973
B20: Mountain | C20: Coastal Express | D20: 27 | E20: 8 | F20: 0.2963
B21: Mid-Atlantic | C21: Northline Logistics | D21: 26 | E21: 7 | F21: 0.2692
B22: Midwest | C22: Coastal Express | D22: 36 | E22: 8 | F22: 0.2222
B23: Midwest | C23: Northline Logistics | D23: 18 | E23: 4 | F23: 0.2222
B24: West | C24: Northline Logistics | D24: 27 | E24: 6 | F24: 0.2222
B25: West | C25: Coastal Express | D25: 31 | E25: 6 | F25: 0.1935
B27: Root Cause Breakdown (of all failures)
B28: Failure Reason | C28: Count | D28: % of Failures
B29: CARRIER_DELAY | C29: 83 | D29: 0.5123
B30: ADDR_ERR | C30: 63 | D30: 0.3889
B31: CUST_UNAVAIL | C31: 16 | D31: 0.0988
B33: Lead Time Variance by Carrier (days, ship-to-delivery)
B34: Carrier | C34: Avg Lead Time (days) | D34: Std Dev (days) | E34: Deliveries
B35: Apex Freight | C35: 3.19 | D35: 1.37 | E35: 220
B36: Coastal Express | C36: 3.05 | D36: 1.43 | E36: 186
B37: Northline Logistics | C37: 3.24 | D37: 1.49 | E37: 193
B38: Summit Carriers | C38: 3.02 | D38: 1.31 | E38: 239
